Workbook
Name LastCol: COUNTA('2025'!$7:$7)+1
Name LastCol: COUNTA('2026'!$7:$7)+1
Name LastCol: COUNTA('New Sheet'!$7:$7)+1
Name LastCol: COUNTA(#REF!)+1
Name PrintArea_SET: OFFSET('2025'!#REF!,,,MATCH(REPT("z",255),'2025'!$A:$A),'2025'!LastCol)
Name PrintArea_SET: OFFSET('2026'!#REF!,,,MATCH(REPT("z",255),'2026'!$A:$A),'2026'!LastCol)
Name PrintArea_SET: OFFSET('New Sheet'!#REF!,,,MATCH(REPT("z",255),'New Sheet'!$A:$A),'New Sheet'!LastCol)
Name PrintArea_SET: OFFSET(#REF!,,,MATCH(REPT("z",255),#REF!),LastCol)
Name Savings: [1]Data!$E$3

Sheet Sheet2
A3: Count of JAN | B3: Column Labels
A4: Row Labels | B4: 0 | C4: 42 | D4: 155 | E4: 1079 | F4: 1381 | G4: 2733 | H4: 3092 | I4: Grand Total
A5: Angel One
A6: Coin by Zerodha MF
A7: Coin DCX
A8: Coinbase
A9: Fidelity
A10: Grow
A11: Robinhood
A12: Wazirx
A13: Zerodha
A14: Grand Total

Sheet Loan Payments
A1: Loan Payments | B1: Pending | C1: Total | D1: Cleared | E1: Interest | F1: EMI | H1: Pending | I1: Total
A2: Home Loan | B2: 19932.95 | C2: 22100.72 | D2: =C2-B2 -> 2167.77 | E2: 0.096 | F2: 23000 | H2: 21237.06 | I2: 21237.06
A3: Education Loan | B3: =9920.79 -> 9920.79 | C3: 9920.79 | D3: =C3-B3 -> 0 | E3: 0.0965 | F3: 12675 | H3: 9220.79 | I3: 9220.79
A4: Gold Loan | B4: 31599.82 | C4: 31599.82 | D4: =C4-B4 -> 0 | E4: 0.09 | H4: 16184.06 | I4: 16184.06
A5: Personal Loan | B5: 1791.44 | C5: =11000+4215.16 -> 15215.16 | D5: =C5-B5 -> 13423.72 | E5: 0.121 | F5: 0 | H5: 5065.96 | I5: 9943.62
A6: US Credit Cards | B6: =tblEntertainment3244[[#Totals],[Balance]] -> 2014 | C6: =6000 + 2200 -> 8200 | D6: =C6-B6 -> 6186 | E6: 0 | H6: =tblEntertainment3244[[#Totals],[Balance]] -> 2014 | I6: =tblEntertainment3244[[#Totals],[Balance]] -> 2014
A7: Car Loan | B7: 0 | C7: 5687.02 | D7: =C7-B7 -> 5687.02 | E7: 8
A8: Bike Loan | B8: 0 | C8: 1844.07 | D8: =C8-B8 -> 1844.07 | E8: 8
A9: My HDFC Personal Loan | B9: 0 | C9: 100 | D9: =C9-B9 -> 100
A10: Total | B10: =SUM(B2:B9) -> 65259 | C10: =SUM(C2:C6) -> 87036.49 | D10: =C10-B10 -> 21777.49 | H10: =SUM(H2:H6) -> 53721.87 | I10: =SUM(I2:I6) -> 58599.53

Sheet 2026
A5: =tblRecreation3546[[#Totals],[Invested Total]] -> 18757.47 | G5: =P107 -> 65259
A7: REVENUE
A8: INCOME | B8: JAN | C8: FEB | D8: MAR | E8: APR | F8: MAY | G8: JUN | H8: JUL | I8: AUG | J8: SEP | K8: OCT | L8: NOV | M8: DEC | N8: YEAR | O8: Last Updated on | P8: Column1
A9: Wages Week 1 | C9: 2729.16 | D9: 40 | E9: 3016.99 | F9: 3016.99 | G9: =30.16+2986.83 -> 3016.99 | H9: =3020.05 + 30.5 -> 3050.55 | N9: =SUM(tblIncome2833[[#This Row],[JAN]:[DEC]]) -> 14870.68 | O9: 46224
A10: Wages Week 2 | C10: 3007 | D10: 3007 | E10: 3016.99 | F10: =2986.83+30.16 -> 3016.99 | G10: =2986.83+30.16 -> 3016.99 | H10: =3020.05 + 30.5 -> 3050.55 | N10: =SUM(tblIncome2833[[#This Row],[JAN]:[DEC]]) -> 18115.52
A11: Wages Week (Kooli Pani, PhoneBill reimbursment) | B11: 1600 | G11: 240 | N11: =SUM(tblIncome2833[[#This Row],[JAN]:[DEC]]) -> 1840
A12: Wages Week (taxes, HSA money) | C12: =1030 + 4185 -> 5215 | D12: 30 | E12: =94.39+75 -> 169.39 | F12: =70.31+9.97+29.73 -> 110.01 | N12: =SUM(tblIncome2833[[#This Row],[JAN]:[DEC]]) -> 5524.4
A13: Total | B13: =SUBTOTAL(109,tblIncome2833[JAN]) -> 1600 | C13: =SUBTOTAL(109,tblIncome2833[FEB]) -> 10951.16 | D13: =SUBTOTAL(109,tblIncome2833[MAR]) -> 3077 | E13: =SUBTOTAL(109,tblIncome2833[APR]) -> 6203.37 | F13: =SUBTOTAL(109,tblIncome2833[MAY]) -> 6143.99 | G13: =SUBTOTAL(109,tblIncome2833[JUN]) -> 6273.98 | H13: =SUBTOTAL(109,tblIncome2833[JUL]) -> 6101.1 | I13: =SUBTOTAL(109,tblIncome2833[AUG]) -> 0 | J13: =SUBTOTAL(109,tblIncome2833[SEP]) -> 0 | K13: =SUBTOTAL(109,tblIncome2833[OCT]) -> 0 | L13: =SUBTOTAL(109,tblIncome2833[NOV]) -> 0 | M13: =SUBTOTAL(109,tblIncome2833[DEC]) -> 0 | N13: =SUBTOTAL(109,tblIncome2833[YEAR]) -> 40350.6
A15: EXPENSES
A16: HOME | B16: JAN | C16: FEB | D16: MAR | E16: APR | F16: MAY | G16: JUN | H16: JUL | I16: AUG | J16: SEP | K16: OCT | L16: NOV | M16: DEC | N16: YEAR | O16: Last Updated on
A17: Mortgage | B17: 850 | C17: 800 | D17: 800 | E17: 800 | F17: 800 | G17: 400 | N17: =SUM(tblHome2941[[#This Row],[JAN]:[DEC]]) -> 4450 | O17: 46224
A18: Insurance | N18: =SUM(tblHome2941[[#This Row],[JAN]:[DEC]]) -> 0
A19: Deposit | D19: 800 | N19: =SUM(tblHome2941[[#This Row],[JAN]:[DEC]]) -> 800
A20: Utilities | B20: 109 | D20: 94.38 | E20: 59.1 | F20: 59.86 | G20: 59.67 | H20: 37.43 | N20: =SUM(tblHome2941[[#This Row],[JAN]:[DEC]]) -> 419.44
A21: College Expenses(Car + Gas + cofee + flights) | D21: =24.09+7.3+2+23.31+0.1+22.84+26.86+307.23+25+22.02+16.35+15.52+9.03 -> 501.65 | F21: =594.66+51+2.83+10.65+8.31+7.94+2.83+9.88 -> 688.1 | G21: 293.3 | N21: =SUM(tblHome2941[[#This Row],[JAN]:[DEC]]) -> 1483.05
A22: Total | B22: =SUBTOTAL(109,tblHome2941[JAN]) -> 959 | C22: =SUBTOTAL(109,tblHome2941[FEB]) -> 800 | D22: =SUBTOTAL(109,tblHome2941[MAR]) -> 2196.03 | E22: =SUBTOTAL(109,tblHome2941[APR]) -> 859.1 | F22: =SUBTOTAL(109,tblHome2941[MAY]) -> 1547.96 | G22: =SUBTOTAL(109,tblHome2941[JUN]) -> 752.97 | H22: =SUBTOTAL(109,tblHome2941[JUL]) -> 37.43 | I22: =SUBTOTAL(109,tblHome2941[AUG]) -> 0 | J22: =SUBTOTAL(109,tblHome2941[SEP]) -> 0 | K22: =SUBTOTAL(109,tblHome2941[OCT]) -> 0 | L22: =SUBTOTAL(109,tblHome2941[NOV]) -> 0 | M22: =SUBTOTAL(109,tblHome2941[DEC]) -> 0 | N22: =SUBTOTAL(109,tblHome2941[YEAR]) -> 7152.49
A24: DAILY LIVING | B24: JAN | C24: FEB | D24: MAR | E24: APR | F24: MAY | G24: JUN | H24: JUL | I24: AUG | J24: SEP | K24: OCT | L24: NOV | M24: DEC | N24: YEAR | O24: Last Updated on
A25: Split Wise | B25: 90 | C25: 270 | N25: =SUM(tblDaily3042[[#This Row],[JAN]:[DEC]]) -> 360 | O25: 46224
A26: Groceries(Indian) | B26: 308 | C26: 244 | D26: 27.64 | E26: 58.3 | F26: 20 | G26: =9.62+29.96 -> 39.58 | N26: =SUM(tblDaily3042[[#This Row],[JAN]:[DEC]]) -> 697.52
A27: Shifting to new places | C27: 85 | N27: =SUM(tblDaily3042[[#This Row],[JAN]:[DEC]]) -> 85
A28: Walmart | D28: =31.62+10.01+15.38+2.61+39.43 -> 99.05 | E28: =45.3+6.16+48.47+25.62+19.47+14.71+37.19 -> 196.92 | F28: =-8.41+40.31+38.67+44.49+27.12+2 -> 144.18 | G28: =19.97+9.94+21.51+2.42+10.06+5.23+34+33+8.94-26 -> 119.07 | H28: =13+8.25+39.48 -> 60.73 | N28: =SUM(tblDaily3042[[#This Row],[JAN]:[DEC]]) -> 619.95
A29: Dining out | C29: 1.87 | D29: =6+16.04+1+11 -> 34.04 | E29: =3.1+17.16+23.75+5.76+1.56+5.3+15.85 -> 72.48 | F29: =7.7+6.92+9.07 -> 23.69 | G29: =2+4.06+12+5.62+1.06+7+3+4.54+1 -> 40.28 | H29: 9.24 | N29: =SUM(tblDaily3042[[#This Row],[JAN]:[DEC]]) -> 181.6
A30: Other home expenses (Amazon, dollar tree, costco) | B30: 96.25 | C30: 64 | D30: =10.62+2.61 -> 13.23 | E30: 58.96 | G30: 63.71 | N30: =SUM(tblDaily3042[[#This Row],[JAN]:[DEC]]) -> 296.15
A31: Fun Activities(Board Games, Outdoor Activities) | F31: 7.28 | G31: =12.49+11.65+ 13 -> 37.14 | N31: =SUM(tblDaily3042[[#This Row],[JAN]:[DEC]]) -> 44.42
A32: Total | B32: =SUBTOTAL(109,tblDaily3042[JAN]) -> 494.25 | C32: =SUBTOTAL(109,tblDaily3042[FEB]) -> 664.87 | D32: =SUBTOTAL(109,tblDaily3042[MAR]) -> 173.96 | E32: =SUBTOTAL(109,tblDaily3042[APR]) -> 386.66 | F32: =SUBTOTAL(109,tblDaily3042[MAY]) -> 195.15 | G32: =SUBTOTAL(109,tblDaily3042[JUN]) -> 299.78 | H32: =SUBTOTAL(109,tblDaily3042[JUL]) -> 69.97 | I32: =SUBTOTAL(109,tblDaily3042[AUG]) -> 0 | J32: =SUBTOTAL(109,tblDaily3042[SEP]) -> 0 | K32: =SUBTOTAL(109,tblDaily3042[OCT]) -> 0 | L32: =SUBTOTAL(109,tblDaily3042[NOV]) -> 0 | M32: =SUBTOTAL(109,tblDaily3042[DEC]) -> 0 | N32: =SUBTOTAL(109,tblDaily3042[YEAR]) -> 2284.64
A34: TRANSPORTATION | B34: JAN | C34: FEB | D34: MAR | E34: APR | F34: MAY | G34: JUN | H34: JUL | I34: AUG | J34: SEP | K34: OCT | L34: NOV | M34: DEC | N34: YEAR | O34: Last Updated on
A35: Public transportation | B35: 4 | C35: 50.84 | D35: =7.5+7.5+7.5 -> 22.5 | E35: =2.57+2.5+2.57+2.57 -> 10.21 | F35: 11.32 | G35: 2.32 | H35: =8.23+3.09+7.72+5 -> 24.04 | N35: =SUM(tblTransportation3143[[#This Row],[JAN]:[DEC]]) -> 125.23 | O35: 46224
A36: Friends transportation | C36: 8.5 | D36: 2.25 | N36: =SUM(tblTransportation3143[[#This Row],[JAN]:[DEC]]) -> 10.75
A37: Cabs | C37: 5.34 | N37: =SUM(tblTransportation3143[[#This Row],[JAN]:[DEC]]) -> 5.34
A38: Total | B38: =SUBTOTAL(109,tblTransportation3143[JAN]) -> 4 | C38: =SUBTOTAL(109,tblTransportation3143[FEB]) -> 64.68 | D38: =SUBTOTAL(109,tblTransportation3143[MAR]) -> 24.75 | E38: =SUBTOTAL(109,tblTransportation3143[APR]) -> 10.21 | F38: =SUBTOTAL(109,tblTransportation3143[MAY]) -> 11.32 | G38: =SUBTOTAL(109,tblTransportation3143[JUN]) -> 2.32 | H38: =SUBTOTAL(109,tblTransportation3143[JUL]) -> 24.04 | I38: =SUBTOTAL(109,tblTransportation3143[AUG]) -> 0 | J38: =SUBTOTAL(109,tblTransportation3143[SEP]) -> 0 | K38: =SUBTOTAL(109,tblTransportation3143[OCT]) -> 0 | L38: =SUBTOTAL(109,tblTransportation3143[NOV]) -> 0 | M38: =SUBTOTAL(109,tblTransportation3143[DEC]) -> 0 | N38: =SUBTOTAL(109,tblTransportation3143[YEAR]) -> 141.32
A40: Credit Card | B40: JAN | C40: FEB | D40: MAR | E40: APR | F40: MAY | G40: JUN | H40: JUL | I40: AUG | J40: SEP | K40: OCT | L40: NOV | M40: DEC | N40: YEAR | O40: Last Updated on | P40: Balance
A41: Chase | B41: 48 | C41: 252 | D41: 300 | E41: 100 | N41: =SUM(tblEntertainment3244[[#This Row],[JAN]:[DEC]]) -> 700 | O41: 46224 | P41: 1000
A42: Amex(fee) | B42: 8.95 | G42: 325 | N42: =SUM(tblEntertainment3244[[#This Row],[JAN]:[DEC]]) -> 333.95 | P42: 0
A43: Capital One | N43: =SUM(tblEntertainment3244[[#This Row],[JAN]:[DEC]]) -> 0 | P43: 0
A44: Discover | C44: 176.62 | D44: 200 | E44: 100 | N44: =SUM(tblEntertainment3244[[#This Row],[JAN]:[DEC]]) -> 476.62 | P44: 1014
A45: Citi | N45: =SUM(tblEntertainment3244[[#This Row],[JAN]:[DEC]]) -> 0 | P45: 0
A46: BOFA | N46: =SUM(tblEntertainment3244[[#This Row],[JAN]:[DEC]]) -> 0
A47: Total | B47: =SUBTOTAL(109,tblEntertainment3244[JAN]) -> 56.95 | C47: =SUBTOTAL(109,tblEntertainment3244[FEB]) -> 428.62 | D47: =SUBTOTAL(109,tblEntertainment3244[MAR]) -> 500 | E47: =SUBTOTAL(109,tblEntertainment3244[APR]) -> 200 | F47: =SUBTOTAL(109,tblEntertainment3244[MAY]) -> 0 | G47: =SUBTOTAL(109,tblEntertainment3244[JUN]) -> 325 | H47: =SUBTOTAL(109,tblEntertainment3244[JUL]) -> 0 | I47: =SUBTOTAL(109,tblEntertainment3244[AUG]) -> 0 | J47: =SUBTOTAL(109,tblEntertainment3244[SEP]) -> 0 | K47: =SUBTOTAL(109,tblEntertainment3244[OCT]) -> 0 | L47: =SUBTOTAL(109,tblEntertainment3244[NOV]) -> 0 | M47: =SUBTOTAL(109,tblEntertainment3244[DEC]) -> 0 | N47: =SUBTOTAL(109,tblEntertainment3244[YEAR]) -> 1510.57 | P47: =SUM(tblEntertainment3244[Balance]) -> 2014
A49: VACATIONS | B49: JAN | C49: FEB | D49: MAR | E49: APR | F49: MAY | G49: JUN | H49: JUL | I49: AUG | J49: SEP | K49: OCT | L49: NOV | M49: DEC | N49: YEAR | O49: Last Updated on
A50: Trips | C50: 519 | E50: =22.5+18.5 -> 41 | G50: =386.67+30.04 -> 416.71 | H50: =11.57+4.27+4+18.52+24.32+14.43+15.92+4.42+5.6+54.65+31.99+27.45+28.63+15+7.73+12.22+8.28+18.58 -> 307.58 | N50: =SUM(tblVacations3445[[#This Row],[JAN]:[DEC]]) -> 1284.29
...

Sheet 2026 Visualizations
A76: Category | B76: Jan | C76: Feb | D76: Mar | E76: Apr | F76: May | J76: Month | K76: Normal Spending | L76: Remittances
A77: Rent | B77: =SUM(tblHome2941[[#Totals],[JAN]]) -> 959 | C77: =SUM(tblHome2941[[#Totals],[FEB]]) -> 800 | D77: =SUM(tblHome2941[[#Totals],[MAR]]) -> 2196.03 | E77: =SUM(tblHome2941[[#Totals],[APR]]) -> 859.1 | F77: =SUM(tblHome2941[[#Totals],[MAY]]) -> 1547.96 | J77: Jan | K77: =SUM(B77:B84) -> 2011.72 | L77: =B85 -> 1043
A78: Grociers | B78: =SUM(tblDaily3042[[#Totals],[JAN]]) -> 494.25 | C78: =SUM(tblDaily3042[[#Totals],[FEB]]) -> 664.87 | D78: =SUM(tblDaily3042[[#Totals],[MAR]]) -> 173.96 | E78: =SUM(tblDaily3042[[#Totals],[APR]]) -> 386.66 | F78: =SUM(tblDaily3042[[#Totals],[MAY]]) -> 195.15 | J78: Feb | K78: =SUM(C77:C84) -> 2875.62 | L78: =C85 -> 5430.51
A79: Transportation | B79: =SUM(tblTransportation3143[[#Totals],[JAN]]) -> 4 | C79: =SUM(tblTransportation3143[[#Totals],[FEB]]) -> 64.68 | D79: =SUM(tblTransportation3143[[#Totals],[MAR]]) -> 24.75 | E79: =SUM(tblTransportation3143[[#Totals],[APR]]) -> 10.21 | F79: =SUM(tblTransportation3143[[#Totals],[MAY]]) -> 11.32 | J79: Mar | K79: =SUM(D77:D84) -> 7490.77 | L79: =D85 -> 8866.52
A80: Credit Card | B80: =SUM(tblEntertainment3244[[#Totals],[JAN]]) -> 56.95 | C80: =SUM(tblEntertainment3244[[#Totals],[FEB]]) -> 428.62 | D80: =SUM(tblEntertainment3244[[#Totals],[MAR]]) -> 500 | E80: =SUM(tblEntertainment3244[[#Totals],[APR]]) -> 200 | F80: =SUM(tblEntertainment3244[[#Totals],[MAY]]) -> 0 | J80: Apr | K80: =SUM(E77:E84) -> 7479.65 | L80: =E85 -> 4389.52
A81: Vacation | B81: =SUM(tblVacations3445[[#Totals],[JAN]]) -> 421 | C81: =SUM(tblVacations3445[[#Totals],[FEB]]) -> 586 | D81: =SUM(tblVacations3445[[#Totals],[MAR]]) -> 23.37 | E81: =SUM(tblVacations3445[[#Totals],[APR]]) -> 41 | F81: =SUM(tblVacations3445[[#Totals],[MAY]]) -> 0 | J81: May | K81: =SUM(F77:F84) -> 2176.27 | L81: =F85 -> 3838
A82: Investment | B82: =SUM(tblRecreation3546[[#Totals],[JAN]]) -> 0 | C82: =SUM(tblRecreation3546[[#Totals],[FEB]]) -> 271.94 | D82: =SUM(tblRecreation3546[[#Totals],[MAR]]) -> 4444.49 | E82: =SUM(tblRecreation3546[[#Totals],[APR]]) -> 5816.06 | F82: =SUM(tblRecreation3546[[#Totals],[MAY]]) -> 188.86
A83: Internet bills | B83: =SUM(tblDues3647[[#Totals],[JAN]]) -> 64.53 | C83: =SUM(tblDues3647[[#Totals],[FEB]]) -> 54.51 | D83: =SUM(tblDues3647[[#Totals],[MAR]]) -> 58.17 | E83: =SUM(tblDues3647[[#Totals],[APR]]) -> 58.32 | F83: =SUM(tblDues3647[[#Totals],[MAY]]) -> 59.53
A84: Self care | B84: =SUM(tblPersonal3748[[#Totals],[JAN]]) -> 11.99 | C84: =SUM(tblPersonal3748[[#Totals],[FEB]]) -> 5 | D84: =SUM(tblPersonal3748[[#Totals],[MAR]]) -> 70 | E84: =SUM(tblPersonal3748[[#Totals],[APR]]) -> 108.3 | F84: =SUM(tblPersonal3748[[#Totals],[MAY]]) -> 173.45
A85: Remitances | B85: =SUM(tblFinancial3849[[#Totals],[JAN]]) -> 1043 | C85: =SUM(tblFinancial3849[[#Totals],[FEB]]) -> 5430.51 | D85: =SUM(tblFinancial3849[[#Totals],[MAR]]) -> 8866.52 | E85: =SUM(tblFinancial3849[[#Totals],[APR]]) -> 4389.52 | F85: =SUM(tblFinancial3849[[#Totals],[MAY]]) -> 3838

Sheet 2025
B3: =SUM(tblHome29[AUG]) -> 494.95
A7: REVENUE
A8: INCOME | B8: JAN | C8: FEB | D8: MAR | E8: APR | F8: MAY | G8: JUN | H8: JUL | I8: AUG | J8: SEP | K8: OCT | L8: NOV | M8: DEC | N8: YEAR | O8: Last Updated on
A9: Wages Week 1 | I9: 2209.39 | J9: 2790.32 | K9: 2793.8 | L9: =1293.8+1500 -> 2793.8 | N9: =SUM(tblIncome28[[#This Row],[JAN]:[DEC]]) -> 10587.31 | O9: 45968
A10: Wages Week 2 | I10: 180.25 | J10: 2793 | K10: 2793.8 | L10: 1500 | N10: =SUM(tblIncome28[[#This Row],[JAN]:[DEC]]) -> 7267.05
A11: Wages Week 3 | I11: 2530.16 | N11: =SUM(tblIncome28[[#This Row],[JAN]:[DEC]]) -> 2530.16
A12: Wages Week 4 | I12: 3192.17 | N12: =SUM(tblIncome28[[#This Row],[JAN]:[DEC]]) -> 3192.17
A13: Total | B13: =SUBTOTAL(109,tblIncome28[JAN]) -> 0 | C13: =SUBTOTAL(109,tblIncome28[FEB]) -> 0 | D13: =SUBTOTAL(109,tblIncome28[MAR]) -> 0 | E13: =SUBTOTAL(109,tblIncome28[APR]) -> 0 | F13: =SUBTOTAL(109,tblIncome28[MAY]) -> 0 | G13: =SUBTOTAL(109,tblIncome28[JUN]) -> 0 | H13: =SUBTOTAL(109,tblIncome28[JUL]) -> 0 | I13: =SUBTOTAL(109,tblIncome28[AUG]) -> 8111.97 | J13: =SUBTOTAL(109,tblIncome28[SEP]) -> 5583.32 | K13: =SUBTOTAL(109,tblIncome28[OCT]) -> 5587.6 | L13: =SUBTOTAL(109,tblIncome28[NOV]) -> 4293.8 | M13: =SUBTOTAL(109,tblIncome28[DEC]) -> 0 | N13: =SUBTOTAL(109,tblIncome28[YEAR]) -> 23576.69
A15: EXPENSES
A16: HOME | B16: JAN | C16: FEB | D16: MAR | E16: APR | F16: MAY | G16: JUN | H16: JUL | I16: AUG | J16: SEP | K16: OCT | L16: NOV | M16: DEC | N16: YEAR | O16: Last Updated on
A17: Mortgage | I17: 450 | J17: 585 | K17: 550 | L17: 550 | N17: =SUM(tblHome29[[#This Row],[JAN]:[DEC]]) -> 2135 | O17: 45971
A18: Insurance | I18: 2.29 | N18: =SUM(tblHome29[[#This Row],[JAN]:[DEC]]) -> 2.29
A19: Deposit | J19: 550 | N19: =SUM(tblHome29[[#This Row],[JAN]:[DEC]]) -> 550
A20: Utilities | I20: 42.66 | K20: 29 | L20: 56.67 | N20: =SUM(tblHome29[[#This Row],[JAN]:[DEC]]) -> 128.33
A21: Total | B21: =SUBTOTAL(109,tblHome29[JAN]) -> 0 | C21: =SUBTOTAL(109,tblHome29[FEB]) -> 0 | D21: =SUBTOTAL(109,tblHome29[MAR]) -> 0 | E21: =SUBTOTAL(109,tblHome29[APR]) -> 0 | F21: =SUBTOTAL(109,tblHome29[MAY]) -> 0 | G21: =SUBTOTAL(109,tblHome29[JUN]) -> 0 | H21: =SUBTOTAL(109,tblHome29[JUL]) -> 0 | I21: =SUBTOTAL(109,tblHome29[AUG]) -> 494.95 | J21: =SUBTOTAL(109,tblHome29[SEP]) -> 1135 | K21: =SUBTOTAL(109,tblHome29[OCT]) -> 579 | L21: =SUBTOTAL(109,tblHome29[NOV]) -> 606.67 | M21: =SUBTOTAL(109,tblHome29[DEC]) -> 0 | N21: =SUBTOTAL(109,tblHome29[YEAR]) -> 2815.62
A23: DAILY LIVING | B23: JAN | C23: FEB | D23: MAR | E23: APR | F23: MAY | G23: JUN | H23: JUL | I23: AUG | J23: SEP | K23: OCT | L23: NOV | M23: DEC | N23: YEAR | O23: Last Updated on
A24: Split Wise | K24: 8.24 | N24: =SUM(tblDaily30[[#This Row],[JAN]:[DEC]]) -> 8.24 | O24: 45971
A25: Groceries | I25: 26 | J25: 73.34 | K25: =72.87 + 1.33 + 4.54 -> 78.74 | L25: =8.37 + 6.12 + 9.76 -> 24.25 | N25: =SUM(tblDaily30[[#This Row],[JAN]:[DEC]]) -> 202.33
A26: Dining out | I26: =15.49 + 21.59 -> 37.08 | J26: 53 | K26: 46.28 | L26: 6.95 | N26: =SUM(tblDaily30[[#This Row],[JAN]:[DEC]]) -> 143.31
A27: Other home expenses | I27: 130.61 | J27: 2.26 | N27: =SUM(tblDaily30[[#This Row],[JAN]:[DEC]]) -> 132.87
A28: Total | B28: =SUBTOTAL(109,tblDaily30[JAN]) -> 0 | C28: =SUBTOTAL(109,tblDaily30[FEB]) -> 0 | D28: =SUBTOTAL(109,tblDaily30[MAR]) -> 0 | E28: =SUBTOTAL(109,tblDaily30[APR]) -> 0 | F28: =SUBTOTAL(109,tblDaily30[MAY]) -> 0 | G28: =SUBTOTAL(109,tblDaily30[JUN]) -> 0 | H28: =SUBTOTAL(109,tblDaily30[JUL]) -> 0 | I28: =SUBTOTAL(109,tblDaily30[AUG]) -> 193.69 | J28: =SUBTOTAL(109,tblDaily30[SEP]) -> 128.6 | K28: =SUBTOTAL(109,tblDaily30[OCT]) -> 133.26 | L28: =SUBTOTAL(109,tblDaily30[NOV]) -> 31.2 | M28: =SUBTOTAL(109,tblDaily30[DEC]) -> 0 | N28: =SUBTOTAL(109,tblDaily30[YEAR]) -> 486.75
A30: TRANSPORTATION | B30: JAN | C30: FEB | D30: MAR | E30: APR | F30: MAY | G30: JUN | H30: JUL | I30: AUG | J30: SEP | K30: OCT | L30: NOV | M30: DEC | N30: YEAR | O30: Last Updated on
A31: Public transportation | I31: 101.25 | J31: 265.8 | N31: =SUM(tblTransportation31[[#This Row],[AUG]:[DEC]]) -> 367.05 | O31: 45971
A32: Friends transportation | H32: 15 | I32: 15 | N32: =SUM(tblTransportation31[[#This Row],[AUG]:[DEC]]) -> 15
A33: Cabs | J33: 16.15 | L33: 32 | N33: =SUM(tblTransportation31[[#This Row],[AUG]:[DEC]]) -> 48.15
A34: Total | B34: =SUBTOTAL(109,tblTransportation31[JAN]) -> 0 | C34: =SUBTOTAL(109,tblTransportation31[FEB]) -> 0 | D34: =SUBTOTAL(109,tblTransportation31[MAR]) -> 0 | E34: =SUBTOTAL(109,tblTransportation31[APR]) -> 0 | F34: =SUBTOTAL(109,tblTransportation31[MAY]) -> 0 | G34: =SUBTOTAL(109,tblTransportation31[JUN]) -> 0 | H34: =SUBTOTAL(109,tblTransportation31[JUL]) -> 15 | I34: =SUBTOTAL(109,tblTransportation31[AUG]) -> 116.25 | J34: =SUBTOTAL(109,tblTransportation31[SEP]) -> 281.95 | K34: =SUBTOTAL(109,tblTransportation31[OCT]) -> 0 | L34: =SUBTOTAL(109,tblTransportation31[NOV]) -> 32 | M34: =SUBTOTAL(109,tblTransportation31[DEC]) -> 0 | N34: =SUBTOTAL(109,tblTransportation31[YEAR]) -> 430.2
A36: Credit Card | B36: JAN | C36: FEB | D36: MAR | E36: APR | F36: MAY | G36: JUN | H36: JUL | I36: AUG | J36: SEP | K36: OCT | L36: NOV | M36: DEC | N36: YEAR | O36: Last Updated on | P36: Balance
A37: Chase | J37: 40 | K37: 41 | L37: 44 | N37: =SUM(tblEntertainment32[[#This Row],[JAN]:[DEC]]) -> 125 | O37: 45971 | P37: 4914.16
A38: Amex | I38: 95.25 | J38: 400 | K38: 1700 | L38: =200 + 400 + 300 -> 900 | N38: =SUM(tblEntertainment32[[#This Row],[JAN]:[DEC]]) -> 3095.25 | O38: Still pending few on 10th | P38: 2103
A39: Capital One | N39: =SUM(tblEntertainment32[[#This Row],[JAN]:[DEC]]) -> 0 | P39: 0
A40: Discover | I40: 0 | J40: 124 | N40: =SUM(tblEntertainment32[[#This Row],[JAN]:[DEC]]) -> 124 | P40: 1418
A41: Citi | I41: 0 | N41: =SUM(tblEntertainment32[[#This Row],[JAN]:[DEC]]) -> 0 | P41: 0
A42: BOFA | I42: 0 | N42: =SUM(tblEntertainment32[[#This Row],[JAN]:[DEC]]) -> 0
A43: Total | B43: =SUBTOTAL(109,tblEntertainment32[JAN]) -> 0 | C43: =SUBTOTAL(109,tblEntertainment32[FEB]) -> 0 | D43: =SUBTOTAL(109,tblEntertainment32[MAR]) -> 0 | E43: =SUBTOTAL(109,tblEntertainment32[APR]) -> 0 | F43: =SUBTOTAL(109,tblEntertainment32[MAY]) -> 0 | G43: =SUBTOTAL(109,tblEntertainment32[JUN]) -> 0 | H43: =SUBTOTAL(109,tblEntertainment32[JUL]) -> 0 | I43: =SUBTOTAL(109,tblEntertainment32[AUG]) -> 95.25 | J43: =SUBTOTAL(109,tblEntertainment32[SEP]) -> 564 | K43: =SUBTOTAL(109,tblEntertainment32[OCT]) -> 1741 | L43: =SUBTOTAL(109,tblEntertainment32[NOV]) -> 944 | M43: =SUBTOTAL(109,tblEntertainment32[DEC]) -> 0 | N43: =SUBTOTAL(109,tblEntertainment32[YEAR]) -> 3344.25 | P43: =SUM(tblEntertainment32[Balance]) -> 8435.16
A45: VACATIONS | B45: JAN | C45: FEB | D45: MAR | E45: APR | F45: MAY | G45: JUN | H45: JUL | I45: AUG | J45: SEP | K45: OCT | L45: NOV | M45: DEC | N45: YEAR | O45: Last Updated on
A46: Trips | L46: =157.46 + 69.46 -> 226.92 | N46: =SUM(tblVacations34[[#This Row],[JAN]:[DEC]]) -> 226.92 | O46: 45971
A47: Accommodations | N47: =SUM(tblVacations34[[#This Row],[JAN]:[DEC]]) -> 0
A48: Movies | I48: 26.49 | J48: 37.52 | K48: 26.49 | N48: =SUM(tblVacations34[[#This Row],[JAN]:[DEC]]) -> 90.5
A49: Airlines | I49: 80 | K49: 586 | N49: =SUM(tblVacations34[[#This Row],[JAN]:[DEC]]) -> 666
A50: Rental car | N50: =SUM(tblVacations34[[#This Row],[JAN]:[DEC]]) -> 0
...

Sheet 2025 Visualizations
A23: Category | B23: Aug | C23: Sept | D23: OCT | E23: Nov | F23: Dec
A24: Rent | B24: =SUM(tblHome29[AUG]) -> 494.95 | C24: =SUM(tblHome29[SEP]) -> 1135 | D24: =SUM(tblHome29[OCT]) -> 579 | E24: =SUM(tblHome29[NOV]) -> 606.67 | F24: =SUM(tblHome29[DEC]) -> 0
A25: Grociers | B25: =SUM(tblDaily30[AUG]) -> 193.69 | C25: =SUM(tblDaily30[SEP]) -> 128.6 | D25: =SUM(tblDaily30[OCT]) -> 133.26 | E25: =SUM(tblDaily30[NOV]) -> 31.2 | F25: =SUM(tblDaily30[DEC]) -> 0
A26: Transportation | B26: =SUM(tblTransportation31[AUG]) -> 116.25 | C26: =SUM(tblTransportation31[SEP]) -> 281.95 | D26: =SUM(tblTransportation31[OCT]) -> 0 | E26: =SUM(tblTransportation31[NOV]) -> 32 | F26: =SUM(tblTransportation31[DEC]) -> 0
A27: Credit Card | B27: =SUM(tblEntertainment32[AUG]) -> 95.25 | C27: =SUM(tblEntertainment32[SEP]) -> 564 | D27: =SUM(tblEntertainment32[OCT]) -> 1741 | E27: =SUM(tblEntertainment32[NOV]) -> 944 | F27: =SUM(tblEntertainment32[DEC]) -> 0
A28: Vacation | B28: =SUM(tblVacations34[AUG]) -> 106.49 | C28: =SUM(tblVacations34[SEP]) -> 37.52 | D28: =SUM(tblVacations34[OCT]) -> 612.49 | E28: =SUM(tblVacations34[NOV]) -> 226.92 | F28: =SUM(tblVacations34[DEC]) -> 0
A29: Investment | B29: =SUM(tblRecreation35[AUG]) -> 1268.34 | C29: =SUM(tblRecreation35[SEP]) -> 0 | D29: =SUM(tblRecreation35[OCT]) -> 374 | E29: =SUM(tblRecreation35[NOV]) -> 155 | F29: =SUM(tblRecreation35[DEC]) -> 0
A30: Internet bills | B30: =SUM(tblDues36[AUG]) -> 23.32 | C30: =SUM(tblDues36[SEP]) -> 52.16 | D30: =SUM(tblDues36[OCT]) -> 62.92 | E30: =SUM(tblDues36[NOV]) -> 12.99 | F30: =SUM(tblDues36[DEC]) -> 10
A31: Self care | B31: =SUM(tblPersonal37[AUG]) -> 12.99 | C31: =SUM(tblPersonal37[SEP]) -> 0 | D31: =SUM(tblPersonal37[OCT]) -> 71.64 | E31: =SUM(tblPersonal37[NOV]) -> 13.94 | F31: =SUM(tblPersonal37[DEC]) -> 0
A32: Remitances | B32: =SUM(tblFinancial38[AUG]) -> 3838.61 | C32: =SUM(tblFinancial38[SEP]) -> 4950 | D32: =SUM(tblFinancial38[OCT]) -> 2964.72 | E32: =SUM(tblFinancial38[NOV]) -> 1493.47 | F32: =SUM(tblFinancial38[DEC]) -> 0
A35: Month | B35: Normal Spending | C35: Remittances
A36: Aug | B36: =SUM(B23:B31) -> 2311.28 | C36: =B32 -> 3838.61
A37: Sept | B37: =SUM(C23:C31) -> 2199.23 | C37: =C32 -> 4950
A38: Oct | B38: =SUM(D23:D31) -> 3574.31 | C38: =D32 -> 2964.72
A39: Nov | B39: =SUM(E23:E31) -> 2022.72 | C39: =E32 -> 1493.47
A40: Dec | B40: =SUM(F23:F31) -> 10 | C40: =F32 -> 0

Sheet Sheet1
A1: BUDGET WHEEL
A2: Monthly income | F2: Savings amount
A3: 5738 | F3: =Savings -> 2577
F5: Value calculated automatically

Sheet Personal net worth
M1: Cash and Cash Equivalent | N1: =SUMIF(#REF!,'[2]Personal net worth'!M1,#REF!)+ROW(M1)/10000 -> #REF! | O1: =_xlfn.RANK.EQ(N1,$N$1:$N$5,0) -> #REF! | Q1: =INDEX($M$1:$N$5,MATCH(5,$O$1:$O$5,0),1) -> #N/A | R1: =ROUND(INDEX($M$1:$N$5,MATCH(5,$O$1:$O$5,0),2),2) -> #N/A | T1: Total Assets | U1: =SUM(#REF!) -> #REF!
M2: Properties | N2: =SUMIF(#REF!,'[2]Personal net worth'!M2,#REF!)+ROW(M2)/10000 -> #REF! | O2: =_xlfn.RANK.EQ(N2,$N$1:$N$5,0) -> #REF! | Q2: =INDEX($M$1:$N$5,MATCH(4,$O$1:$O$5,0),1) -> #N/A | R2: =ROUND(INDEX($M$1:$N$5,MATCH(4,$O$1:$O$5,0),2),2) -> #N/A | T2: Total Debts | U2: =SUM(#REF!) -> #REF!
C3: PERSONAL NET WORTH | G3: ASSETS VS DEBT | M3: Investments | N3: =SUMIF(#REF!,'[2]Personal net worth'!M3,#REF!)+ROW(M3)/10000 -> #REF! | O3: =_xlfn.RANK.EQ(N3,$N$1:$N$5,0) -> #REF! | Q3: =INDEX($M$1:$N$5,MATCH(3,$O$1:$O$5,0),1) -> #N/A | R3: =ROUND(INDEX($M$1:$N$5,MATCH(3,$O$1:$O$5,0),2),2) -> #N/A
C4: =E5-E7 -> #REF! | M4: Retirement Savings | N4: =SUMIF(#REF!,'[2]Personal net worth'!M4,#REF!)+ROW(M4)/10000 -> #REF! | O4: =_xlfn.RANK.EQ(N4,$N$1:$N$5,0) -> #REF! | Q4: =INDEX($M$1:$N$5,MATCH(2,$O$1:$O$5,0),1) -> #N/A | R4: =ROUND(INDEX($M$1:$N$5,MATCH(2,$O$1:$O$5,0),2),2) -> #N/A
D5: Total assets | E5: =SUM(#REF!) -> #REF! | M5: Life Insurance | N5: =SUMIF(#REF!,'[2]Personal net worth'!M5,#REF!)+ROW(M5)/10000 -> #REF! | O5: =_xlfn.RANK.EQ(N5,$N$1:$N$5,0) -> #REF! | Q5: =INDEX($M$1:$N$5,MATCH(1,$O$1:$O$5,0),1) -> #N/A | R5: =ROUND(INDEX($M$1:$N$5,MATCH(1,$O$1:$O$5,0),2),2) -> #N/A
D7: Total debt | E7: =SUM(#REF!) -> #REF!
C9: SUMMARY OF ASSETS
H11: =Q5 -> #N/A | I11: =R5 -> #N/A
H13: =Q4 -> #N/A | I13: =R4 -> #N/A
H15: =Q3 -> #N/A | I15: =R3 -> #N/A
H17: =Q2 -> #N/A | I17: =R2 -> #N/A
H19: =Q1 -> #N/A | I19: =R1 -> #N/A

Sheet New Sheet
B3: =SUM(tblHome29413[AUG]) -> 0
A7: REVENUE
A8: INCOME | B8: JAN | C8: FEB | D8: MAR | E8: APR | F8: MAY | G8: JUN | H8: JUL | I8: AUG | J8: SEP | K8: OCT | L8: NOV | M8: DEC | N8: YEAR | O8: Last Updated on
A9: Wages Week 1 | B9: 1600 | N9: =SUM(tblIncome28332[[#This Row],[JAN]:[DEC]]) -> 1600 | O9: 46058
A10: Wages Week 2 | N10: =SUM(tblIncome28332[[#This Row],[JAN]:[DEC]]) -> 0
A11: Wages Week 3 | N11: =SUM(tblIncome28332[[#This Row],[JAN]:[DEC]]) -> 0
A12: Wages Week 4 | N12: =SUM(tblIncome28332[[#This Row],[JAN]:[DEC]]) -> 0
A13: Total | B13: =SUBTOTAL(109,tblIncome28332[JAN]) -> 1600 | C13: =SUBTOTAL(109,tblIncome28332[FEB]) -> 0 | D13: =SUBTOTAL(109,tblIncome28332[MAR]) -> 0 | E13: =SUBTOTAL(109,tblIncome28332[APR]) -> 0 | F13: =SUBTOTAL(109,tblIncome28332[MAY]) -> 0 | G13: =SUBTOTAL(109,tblIncome28332[JUN]) -> 0 | H13: =SUBTOTAL(109,tblIncome28332[JUL]) -> 0 | I13: =SUBTOTAL(109,tblIncome28332[AUG]) -> 0 | J13: =SUBTOTAL(109,tblIncome28332[SEP]) -> 0 | K13: =SUBTOTAL(109,tblIncome28332[OCT]) -> 0 | L13: =SUBTOTAL(109,tblIncome28332[NOV]) -> 0 | M13: =SUBTOTAL(109,tblIncome28332[DEC]) -> 0 | N13: =SUBTOTAL(109,tblIncome28332[YEAR]) -> 1600
A15: EXPENSES
A16: HOME | B16: JAN | C16: FEB | D16: MAR | E16: APR | F16: MAY | G16: JUN | H16: JUL | I16: AUG | J16: SEP | K16: OCT | L16: NOV | M16: DEC | N16: YEAR | O16: Last Updated on
A17: Mortgage | B17: 850 | N17: =SUM(tblHome29413[[#This Row],[JAN]:[DEC]]) -> 850 | O17: 46058
A18: Insurance | N18: =SUM(tblHome29413[[#This Row],[JAN]:[DEC]]) -> 0
A19: Deposit | N19: =SUM(tblHome29413[[#This Row],[JAN]:[DEC]]) -> 0
A20: Utilities | B20: 109 | N20: =SUM(tblHome29413[[#This Row],[JAN]:[DEC]]) -> 109
A21: Total | B21: =SUBTOTAL(109,tblHome29413[JAN]) -> 959 | C21: =SUBTOTAL(109,tblHome29413[FEB]) -> 0 | D21: =SUBTOTAL(109,tblHome29413[MAR]) -> 0 | E21: =SUBTOTAL(109,tblHome29413[APR]) -> 0 | F21: =SUBTOTAL(109,tblHome29413[MAY]) -> 0 | G21: =SUBTOTAL(109,tblHome29413[JUN]) -> 0 | H21: =SUBTOTAL(109,tblHome29413[JUL]) -> 0 | I21: =SUBTOTAL(109,tblHome29413[AUG]) -> 0 | J21: =SUBTOTAL(109,tblHome29413[SEP]) -> 0 | K21: =SUBTOTAL(109,tblHome29413[OCT]) -> 0 | L21: =SUBTOTAL(109,tblHome29413[NOV]) -> 0 | M21: =SUBTOTAL(109,tblHome29413[DEC]) -> 0 | N21: =SUBTOTAL(109,tblHome29413[YEAR]) -> 959
A23: DAILY LIVING | B23: JAN | C23: FEB | D23: MAR | E23: APR | F23: MAY | G23: JUN | H23: JUL | I23: AUG | J23: SEP | K23: OCT | L23: NOV | M23: DEC | N23: YEAR | O23: Last Updated on
A24: Split Wise | B24: 90 | N24: =SUM(tblDaily30424[[#This Row],[JAN]:[DEC]]) -> 90 | O24: 46058
A25: Groceries | B25: 308 | C25: 69 | N25: =SUM(tblDaily30424[[#This Row],[JAN]:[DEC]]) -> 377
A26: Dining out | N26: =SUM(tblDaily30424[[#This Row],[JAN]:[DEC]]) -> 0
A27: Other home expenses (Amazon) | B27: 96.25 | C27: 48 | N27: =SUM(tblDaily30424[[#This Row],[JAN]:[DEC]]) -> 144.25
A28: Total | B28: =SUBTOTAL(109,tblDaily30424[JAN]) -> 494.25 | C28: =SUBTOTAL(109,tblDaily30424[FEB]) -> 117 | D28: =SUBTOTAL(109,tblDaily30424[MAR]) -> 0 | E28: =SUBTOTAL(109,tblDaily30424[APR]) -> 0 | F28: =SUBTOTAL(109,tblDaily30424[MAY]) -> 0 | G28: =SUBTOTAL(109,tblDaily30424[JUN]) -> 0 | H28: =SUBTOTAL(109,tblDaily30424[JUL]) -> 0 | I28: =SUBTOTAL(109,tblDaily30424[AUG]) -> 0 | J28: =SUBTOTAL(109,tblDaily30424[SEP]) -> 0 | K28: =SUBTOTAL(109,tblDaily30424[OCT]) -> 0 | L28: =SUBTOTAL(109,tblDaily30424[NOV]) -> 0 | M28: =SUBTOTAL(109,tblDaily30424[DEC]) -> 0 | N28: =SUBTOTAL(109,tblDaily30424[YEAR]) -> 611.25
A30: TRANSPORTATION | B30: JAN | C30: FEB | D30: MAR | E30: APR | F30: MAY | G30: JUN | H30: JUL | I30: AUG | J30: SEP | K30: OCT | L30: NOV | M30: DEC | N30: YEAR | O30: Last Updated on
A31: Public transportation | B31: 4 | N31: =SUM(tblTransportation31435[[#This Row],[JAN]:[DEC]]) -> 4 | O31: 46058
A32: Friends transportation | N32: =SUM(tblTransportation31435[[#This Row],[JAN]:[DEC]]) -> 0
A33: Cabs | N33: =SUM(tblTransportation31435[[#This Row],[JAN]:[DEC]]) -> 0
A34: Total | B34: =SUBTOTAL(109,tblTransportation31435[JAN]) -> 4 | C34: =SUBTOTAL(109,tblTransportation31435[FEB]) -> 0 | D34: =SUBTOTAL(109,tblTransportation31435[MAR]) -> 0 | E34: =SUBTOTAL(109,tblTransportation31435[APR]) -> 0 | F34: =SUBTOTAL(109,tblTransportation31435[MAY]) -> 0 | G34: =SUBTOTAL(109,tblTransportation31435[JUN]) -> 0 | H34: =SUBTOTAL(109,tblTransportation31435[JUL]) -> 0 | I34: =SUBTOTAL(109,tblTransportation31435[AUG]) -> 0 | J34: =SUBTOTAL(109,tblTransportation31435[SEP]) -> 0 | K34: =SUBTOTAL(109,tblTransportation31435[OCT]) -> 0 | L34: =SUBTOTAL(109,tblTransportation31435[NOV]) -> 0 | M34: =SUBTOTAL(109,tblTransportation31435[DEC]) -> 0 | N34: =SUBTOTAL(109,tblTransportation31435[YEAR]) -> 4
A36: Credit Card | B36: JAN | C36: FEB | D36: MAR | E36: APR | F36: MAY | G36: JUN | H36: JUL | I36: AUG | J36: SEP | K36: OCT | L36: NOV | M36: DEC | N36: YEAR | O36: Last Updated on | P36: Balance
A37: Chase | B37: 48 | C37: 52 | N37: =SUM(tblEntertainment32446[[#This Row],[JAN]:[DEC]]) -> 100 | O37: 46058 | P37: 5539
A38: Amex | B38: 8.95 | N38: =SUM(tblEntertainment32446[[#This Row],[JAN]:[DEC]]) -> 8.95 | P38: 0
A39: Capital One | N39: =SUM(tblEntertainment32446[[#This Row],[JAN]:[DEC]]) -> 0 | P39: 0
A40: Discover | N40: =SUM(tblEntertainment32446[[#This Row],[JAN]:[DEC]]) -> 0 | P40: 2123
A41: Citi | N41: =SUM(tblEntertainment32446[[#This Row],[JAN]:[DEC]]) -> 0 | P41: 0
A42: BOFA | N42: =SUM(tblEntertainment32446[[#This Row],[JAN]:[DEC]]) -> 0
A43: Total | B43: =SUBTOTAL(109,tblEntertainment32446[JAN]) -> 56.95 | C43: =SUBTOTAL(109,tblEntertainment32446[FEB]) -> 52 | D43: =SUBTOTAL(109,tblEntertainment32446[MAR]) -> 0 | E43: =SUBTOTAL(109,tblEntertainment32446[APR]) -> 0 | F43: =SUBTOTAL(109,tblEntertainment32446[MAY]) -> 0 | G43: =SUBTOTAL(109,tblEntertainment32446[JUN]) -> 0 | H43: =SUBTOTAL(109,tblEntertainment32446[JUL]) -> 0 | I43: =SUBTOTAL(109,tblEntertainment32446[AUG]) -> 0 | J43: =SUBTOTAL(109,tblEntertainment32446[SEP]) -> 0 | K43: =SUBTOTAL(109,tblEntertainment32446[OCT]) -> 0 | L43: =SUBTOTAL(109,tblEntertainment32446[NOV]) -> 0 | M43: =SUBTOTAL(109,tblEntertainment32446[DEC]) -> 0 | N43: =SUBTOTAL(109,tblEntertainment32446[YEAR]) -> 108.95 | P43: =SUM(tblEntertainment32446[Balance]) -> 7662
A45: VACATIONS | B45: JAN | C45: FEB | D45: MAR | E45: APR | F45: MAY | G45: JUN | H45: JUL | I45: AUG | J45: SEP | K45: OCT | L45: NOV | M45: DEC | N45: YEAR | O45: Last Updated on
A46: Trips | N46: =SUM(tblVacations34457[[#This Row],[JAN]:[DEC]]) -> 0
A47: Accommodations | N47: =SUM(tblVacations34457[[#This Row],[JAN]:[DEC]]) -> 0 | O47: 46058
A48: Movies | N48: =SUM(tblVacations34457[[#This Row],[JAN]:[DEC]]) -> 0
A49: Airlines | B49: 421 | N49: =SUM(tblVacations34457[[#This Row],[JAN]:[DEC]]) -> 421
A50: Rental car | N50: =SUM(tblVacations34457[[#This Row],[JAN]:[DEC]]) -> 0
...
